L'évaluation du script a levé une exception qui n'est pas une ScriptException mais une class org.python.core.PyException.
Merci de faire un rapport de bug contre la PLM, avec tous les détails nécessaires pour reproduire le problème.
Message de l'exception: null
org.python.core.Py.IOError(Py.java:159)
org.python.core.io.StreamIO.write(StreamIO.java:132)
org.python.core.io.BufferedWriter.flush(BufferedWriter.java:78)
org.python.core.io.TextIOBase.flush(TextIOBase.java:148)
org.python.core.PyFile.file_flush(PyFile.java:431)
org.python.core.PyFile.flush(PyFile.java:435)
org.python.core.StdoutWrapper.print(StdoutWrapper.java:134)
org.python.core.StdoutWrapper.print(StdoutWrapper.java:198)
org.python.core.Py.displayException(Py.java:1007)
org.python.core.PyException.printStackTrace(PyException.java:79)
org.python.core.PyException.toString(PyException.java:98)
java.lang.Throwable.<init>(Throwable.java:311)
java.lang.Exception.<init>(Exception.java:102)
javax.script.ScriptException.<init>(ScriptException.java:65)
org.python.jsr223.PyScriptEngine.scriptException(PyScriptEngine.java:192)
org.python.jsr223.PyScriptEngine.eval(PyScriptEngine.java:43)
org.python.jsr223.PyScriptEngine.eval(PyScriptEngine.java:33)
javax.script.AbstractScriptEngine.eval(AbstractScriptEngine.java:264)
plm.core.lang.ScriptingLanguage.runEntity(Unknown Source)
plm.universe.World$1.run(Unknown Source)
java.lang.Thread.run(Thread.java:745)
