Script evaluation raised an exception that is not a ScriptException but a class org.python.core.PyException.
 Please report this as a bug against the PLM, with all details allowing to reproduce it.
Exception message: null
org.python.core.Py.IOError(Py.java:159)
org.python.core.io.StreamIO.write(StreamIO.java:132)
org.python.core.io.BufferedWriter.flush(BufferedWriter.java:78)
org.python.core.io.TextIOBase.flush(TextIOBase.java:148)
org.python.core.PyFile.file_flush(PyFile.java:431)
org.python.core.PyFile.flush(PyFile.java:435)
org.python.core.StdoutWrapper.print(StdoutWrapper.java:134)
org.python.core.StdoutWrapper.print(StdoutWrapper.java:198)
org.python.core.Py.displayException(Py.java:1007)
org.python.core.PyException.printStackTrace(PyException.java:79)
org.python.core.PyException.toString(PyException.java:98)
java.lang.Throwable.<init>(Throwable.java:311)
java.lang.Exception.<init>(Exception.java:102)
javax.script.ScriptException.<init>(ScriptException.java:63)
org.python.jsr223.PyScriptEngine.scriptException(PyScriptEngine.java:192)
org.python.jsr223.PyScriptEngine.eval(PyScriptEngine.java:43)
org.python.jsr223.PyScriptEngine.eval(PyScriptEngine.java:33)
javax.script.AbstractScriptEngine.eval(AbstractScriptEngine.java:264)
plm.core.lang.ScriptingLanguage.runEntity(Unknown Source)
plm.universe.World$1.run(Unknown Source)
java.lang.Thread.run(Thread.java:745)
