Erreur inconnue (veuillez faire un rapport de bug) : <type 'exceptions.AttributeError'>\n
Sa valeur est : AttributeError("'plm.core.lang.LangPython' object has no attribute 'forward'",)
  File "<script>", line 0, in <module>
  File "<script>", line 58, in avance
  File "<script>", line -6, in forward
